Workbook

Sheet Sales_Raw
A1: OrderID | B1: OrderDate | C1: Region | D1: State | E1: Salesperson | F1: CustomerName | G1: Category | H1: ProductID | I1: ProductName | J1: Units | K1: UnitPrice | L1: Discount | M1: Sales | N1: Target | O1: ShipDate | P1: DeliveryDate | Q1: PaymentMethod | R1: CustomerType | S1: Rating | T1: Notes
A2: O0001 | B2: 45798 | C2: East | D2: New York | E2: John Smith | F2: Sara Khan | G2: Accessory | H2: P112 | I2: PowerBank | J2: 3 | K2: 49 | L2: 0 | M2: 147 | N2: 2500 | O2: 45800 | P2: 45802 | Q2: Credit Card | R2: Corporate | S2: 4 | T2: normal
A3: O0002 | B3: 45777 | C3: East | D3: New York | E3: Sara Khan | F3: Sara Khan | G3: Laptop | H3: P104 | I3: Inspiron 15 | J3: 1 | K3: 749 | L3: 0.15 | M3: 636.65 | N3: 500 | O3: 45782 | P3: 45787 | Q3: Bank Transfer | R3: New | S3: 4 | T3: NORMAL
A4: O0003 | B4: 46015 | C4: North | D4: Illinois | E4: Amit Shah | F4: PRIYA PATEL | G4: Laptop | H4: P103 | I4: ThinkPad E14 | J4: 5 | K4: 899 | L4: 0.02 | M4: 4405.1 | N4: 500 | O4: 46019 | P4: 46022 | Q4: Credit Card | R4: Returning | S4: 1 | T4: ok
A5: O0004 | B5: 45680 | C5: North | D5: Minnesota | E5: Rahul Mehta | F5: John Smith | G5: Tablet | H5: P105 | I5: iPad Air | J5: 2 | K5: 599 | L5: 0.1 | M5: 1078.2 | N5: 300 | O5: 45684 | P5: 45689 | Q5: Cash | R5: Corporate | S5: 2 | T5: refund pending
A6: O0005 | B6: 45774 | C6: East | D6: New York | E6: Neha Joshi | F6: Rahul Shah | G6: Accessory | H6: P111 | I6: Mouse | J6: 14 | K6: 39 | L6: 0.02 | M6: 535.08 | N6: 5000 | O6: 45777 | P6: 45778 | Q6: Cash | R6: Returning | S6: 3 | T6: urgent
A7: O0006 | B7: 46001 | C7: North | D7: Michigan | E7: Priya Patel | F7: Sara Khan | G7: Laptop | H7: P104 | I7: Inspiron 15 | J7: 15 | K7: 749 | L7: 0 | M7: 11235 | N7: 1500 | O7: 46004 | P7: 46010 | Q7: UPI | R7: New | S7: 4 | T7: follow-up
A8: O0007 | B8: 45943 | C8: North | D8: Minnesota | E8: Rahul Mehta | F8: Rahul Shah | G8: Accessory | H8: P112 | I8: PowerBank | J8: 6 | K8: 49 | L8: 0 | M8: 294 | N8: 500 | O8: 45945 | P8: 45951 | Q8: Bank Transfer | R8: Returning | S8: 1 | T8: urgent
A9: O0008 | B9: 45913 | C9: North | D9: Illinois | E9: Priya Patel | F9: rAhUl shAh | G9: Accessory | H9: P111 | I9: Mouse | J9: 8 | K9: 39 | L9: 0.02 | M9: 305.76 | N9: 750 | O9: 45917 | P9: 45923 | Q9: Cash | R9: Corporate | S9: 5 | T9: follow-up
A10: O0009 | B10: 45728 | C10: South | D10: Georgia | E10: Priya Patel | F10: Rahul Shah | G10: Laptop | H10: P104 | I10: Inspiron 15 | J10: 2 | K10: 749 | L10: 0 | M10: 1498 | N10: 5000 | O10: 45733 | P10: 45737 | Q10: UPI | R10: Corporate | S10: 4 | T10: NORMAL
A11: O0010 | B11: 45963 | C11: East | D11: Massachusetts | E11: Sara Khan | F11: Rahul Shah | G11: Audio | H11: P107 | I11: AirPods | J11: 5 | K11: 179 | L11: 0.15 | M11: 760.75 | N11: 5000 | O11: 45967 | P11: 45972 | Q11: Credit Card | R11: Corporate | S11: 5
A12: O0011 | B12: 45715 | C12: North | D12: Minnesota | E12: Sara Khan | F12: Sara Khan | G12: Tablet | H12: P106 | I12: Galaxy Tab | J12: 3 | K12: 499 | L12: 0.1 | M12: 1347.3 | N12: 300 | O12: 45718 | P12: 45722 | Q12: Cash | R12: Corporate | S12: 2 | T12: NORMAL
A13: O0012 | B13: 45985 | C13: East | D13: New Jersey | E13: John Smith | F13: rAhUl shAh | G13: Tablet | H13: P105 | I13: iPad Air | J13: 4 | K13: 599 | L13: 0.02 | M13: 2348.08 | N13: 750 | O13: 45990 | P13: 45995 | Q13: Credit Card | R13: Corporate | S13: 3 | T13: follow-up
A14: O0013 | B14: 45815 | C14: East | D14: New York | E14: Sara Khan | F14: Rahul Shah | G14: Tablet | H14: P106 | I14: Galaxy Tab | J14: 4 | K14: 499 | L14: 0.15 | M14: 1696.6 | N14: 300 | O14: 45817 | P14: 45818 | Q14: Bank Transfer | R14: New | S14: 5
A15: O0014 | B15: 45901 | C15: West | D15: California | E15: Neha Joshi | F15: John Smith | G15: Accessory | H15: P111 | I15: Mouse | J15: 5 | K15: 39 | L15: 0.15 | M15: 165.75 | N15: 5000 | O15: 45906 | P15: 45908 | Q15: UPI | R15: Corporate | S15: 2 | T15: refund pending
A16: O0015 | B16: 45990 | C16: North | D16: Michigan | E16: Priya Patel | F16: Rahul Shah | G16: Accessory | H16: P111 | I16: Mouse | J16: 15 | K16: 39 | L16: 0.15 | M16: 497.25 | N16: 1000 | O16: 45993 | P16: 45997 | Q16: UPI | R16: New | S16: 3 | T16: normal
A17: O0016 | B17: 45661 | C17: West | D17: Washington | E17: Amit Shah | F17: Rahul Shah | G17: Laptop | H17: P104 | I17: Inspiron 15 | J17: 11 | K17: 749 | L17: 0 | M17: 8239 | N17: 500 | O17: 45662 | P17: 45668 | Q17: Cash | R17: New | S17: 5 | T17: urgent
A18: O0017 | B18: 45767 | C18: North | D18: Minnesota | E18: Priya Patel | F18: Neha Joshi | G18: Audio | H18: P108 | I18: Buds Pro | J18: 12 | K18: 129 | L18: 0.15 | M18: 1315.8 | N18: 1500 | O18: 45772 | P18: 45774 | Q18: Bank Transfer | R18: Returning | S18: 2 | T18: normal
A19: O0018 | B19: 45839 | C19: East | D19: New Jersey | E19: Sara Khan | F19: Sara Khan | G19: Audio | H19: P107 | I19: AirPods | J19: 8 | K19: 179 | L19: 0 | M19: 1432 | N19: 2500 | O19: 45843 | P19: 45847 | Q19: Credit Card | R19: New | S19: 4 | T19: refund pending
A20: O0019 | B20: 45756 | C20: North | D20: Illinois | E20: Rahul Mehta | F20: rAhUl shAh | G20: Laptop | H20: P104 | I20: Inspiron 15 | J20: 8 | K20: 749 | L20: 0.02 | M20: 5872.16 | N20: 1000 | O20: 45758 | P20: 45763 | Q20: Bank Transfer | R20: New | S20: 1 | T20: follow-up
A21: O0020 | B21: 45934 | C21: East | D21: New York | E21: Neha Joshi | F21: Neha Joshi | G21: Accessory | H21: P111 | I21: Mouse | J21: 15 | K21: 39 | L21: 0.02 | M21: 573.3 | N21: 500 | O21: 45935 | P21: 45936 | Q21: Bank Transfer | R21: New | S21: 4 | T21: normal
A22: O0021 | B22: 45857 | C22: West | D22: Texas | E22: Sara Khan | F22: Neha Joshi | G22: Mobile | H22: P101 | I22: iPhone 15 | J22: 13 | K22: 699 | L22: 0.1 | M22: 8178.3 | N22: 750 | O22: 45860 | P22: 45867 | Q22: Bank Transfer | R22: New | S22: 2 | T22: ok
A23: O0022 | B23: 45935 | C23: West | D23: California | E23: Neha Joshi | F23: John Smith | G23: Accessory | H23: P110 | I23: Keyboard | J23: 6 | K23: 59 | L23: 0 | M23: 354 | N23: 300 | O23: 45936 | P23: 45942 | Q23: UPI | R23: New | S23: 5 | T23: normal
A24: O0023 | B24: 45692 | C24: West | D24: California | E24: John Smith | F24: John Smith | G24: Accessory | H24: P110 | I24: Keyboard | J24: 2 | K24: 59 | L24: 0.15 | M24: 100.3 | N24: 500 | O24: 45694 | P24: 45698 | Q24: Credit Card | R24: Corporate | S24: 1 | T24: follow-up
A25: O0024 | B25: 46000 | C25: North | D25: Michigan | E25: Sara Khan | F25: Sara Khan | G25: Laptop | H25: P104 | I25: Inspiron 15 | J25: 5 | K25: 749 | L25: 0.1 | M25: 3370.5 | N25: 500 | O25: 46003 | P25: 46005 | Q25: Cash | R25: Returning | S25: 3
A26: O0025 | B26: 45976 | C26: East | D26: New York | E26: Rahul Mehta | F26: John Smith | G26: Audio | H26: P108 | I26: Buds Pro | J26: 2 | K26: 129 | L26: 0.15 | M26: 219.3 | N26: 500 | O26: 45981 | P26: 45982 | Q26: UPI | R26: Returning | S26: 1 | T26: urgent
A27: O0026 | B27: 45882 | C27: North | D27: Michigan | E27: John Smith | F27: Sara Khan | G27: Laptop | H27: P103 | I27: ThinkPad E14 | J27: 5 | K27: 899 | L27: 0.15 | M27: 3820.75 | N27: 5000 | O27: 45887 | P27: 45893 | Q27: Credit Card | R27: Corporate | S27: 5 | T27: ok
A28: O0027 | B28: 45717 | C28: East | D28: New York | E28: John Smith | F28: PRIYA PATEL | G28: Tablet | H28: P105 | I28: iPad Air | J28: 9 | K28: 599 | L28: 0.02 | M28: 5283.18 | N28: 750 | O28: 45718 | P28: 45724 | Q28: UPI | R28: Corporate | S28: 3 | T28: urgent
A29: O0028 | B29: 45786 | C29: North | D29: Minnesota | E29: Amit Shah | F29: PRIYA PATEL | G29: Audio | H29: P108 | I29: Buds Pro | J29: 11 | K29: 129 | L29: 0.1 | M29: 1277.1 | N29: 5000 | O29: 45787 | P29: 45788 | Q29: Credit Card | R29: Returning | S29: 2 | T29: refund pending
A30: O0029 | B30: 45884 | C30: North | D30: Illinois | E30: Amit Shah | F30: Rahul Shah | G30: Accessory | H30: P112 | I30: PowerBank | J30: 7 | K30: 49 | L30: 0.15 | M30: 291.55 | N30: 300 | O30: 45889 | P30: 45895 | Q30: UPI | R30: Corporate | S30: 1
A31: O0030 | B31: 45733 | C31: North | D31: Minnesota | E31: Rahul Mehta | F31: Rahul Shah | G31: Monitor | H31: P109 | I31: Monitor 24 | J31: 1 | K31: 229 | L31: 0.05 | M31: 217.55 | N31: 750 | O31: 45737 | P31: 45739 | Q31: UPI | R31: Corporate | S31: 2 | T31: refund pending
A32: O0031 | B32: 45866 | C32: East | D32: Massachusetts | E32: Priya Patel | F32: rAhUl shAh | G32: Monitor | H32: P109 | I32: Monitor 24 | J32: 3 | K32: 229 | L32: 0.02 | M32: 673.26 | N32: 5000 | O32: 45871 | P32: 45877 | Q32: Bank Transfer | R32: New | S32: 2 | T32: refund pending
A33: O0032 | B33: 45785 | C33: North | D33: Michigan | E33: Neha Joshi | F33: Rahul Shah | G33: Accessory | H33: P111 | I33: Mouse | J33: 13 | K33: 39 | L33: 0 | M33: 507 | N33: 1000 | O33: 45788 | P33: 45790 | Q33: UPI | R33: New | S33: 4 | T33: ok
A34: O0033 | B34: 45670 | C34: North | D34: Illinois | E34: Rahul Mehta | F34: Rahul Shah | G34: Laptop | H34: P104 | I34: Inspiron 15 | J34: 6 | K34: 749 | L34: 0.05 | M34: 4269.3 | N34: 5000 | O34: 45672 | P34: 45676 | Q34: Cash | R34: Corporate | S34: 5 | T34: follow-up
A35: O0034 | B35: 45791 | C35: North | D35: Illinois | E35: Neha Joshi | F35: John Smith | G35: Mobile | H35: P102 | I35: Galaxy S24 | J35: 5 | K35: 799 | L35: 0 | M35: 3995 | N35: 300 | O35: 45793 | P35: 45798 | Q35: Cash | R35: Corporate | S35: 3 | T35: follow-up
A36: O0035 | B36: 45755 | C36: East | D36: Massachusetts | E36: John Smith | F36: John Smith | G36: Accessory | H36: P110 | I36: Keyboard | J36: 12 | K36: 59 | L36: 0.1 | M36: 637.2 | N36: 300 | O36: 45758 | P36: 45759 | Q36: UPI | R36: Returning | S36: 4 | T36: normal
A37: O0036 | B37: 45997 | C37: North | D37: Minnesota | E37: Sara Khan | F37: PRIYA PATEL | G37: Tablet | H37: P106 | I37: Galaxy Tab | J37: 15 | K37: 499 | L37: 0.05 | M37: 7110.75 | N37: 1500 | O37: 45998 | P37: 46004 | Q37: Bank Transfer | R37: Returning | S37: 4 | T37: refund pending
A38: O0037 | B38: 45756 | C38: North | D38: Minnesota | E38: Rahul Mehta | F38: John Smith | G38: Laptop | H38: P103 | I38: ThinkPad E14 | J38: 7 | K38: 899 | L38: 0.02 | M38: 6167.14 | N38: 1500 | O38: 45760 | P38: 45766 | Q38: Bank Transfer | R38: Corporate | S38: 1 | T38: ok
A39: O0038 | B39: 45954 | C39: North | D39: Illinois | E39: Sara Khan | F39: Neha Joshi | G39: Audio | H39: P107 | I39: AirPods | J39: 6 | K39: 179 | L39: 0.1 | M39: 966.6 | N39: 1000 | O39: 45959 | P39: 45965 | Q39: UPI | R39: Corporate | S39: 4
A40: O0039 | B40: 45803 | C40: West | D40: Washington | E40: Priya Patel | F40: Rahul Shah | G40: Mobile | H40: P102 | I40: Galaxy S24 | J40: 11 | K40: 799 | L40: 0.15 | M40: 7470.65 | N40: 750 | O40: 45808 | P40: 45814 | Q40: Cash | R40: New | S40: 2 | T40: urgent
...

Sheet Product_Master
A1: ProductID | B1: ProductName | C1: Category | D1: Brand | E1: UnitPrice | F1: Supplier
A2: P101 | B2: iPhone 15 | C2: Mobile | D2: Apple | E2: 699 | F2: TechWorld
A3: P102 | B3: Galaxy S24 | C3: Mobile | D3: Samsung | E3: 799 | F3: Smart Supply
A4: P103 | B4: ThinkPad E14 | C4: Laptop | D4: Lenovo | E4: 899 | F4: Smart Supply
A5: P104 | B5: Inspiron 15 | C5: Laptop | D5: Dell | E5: 749 | F5: Smart Supply
A6: P105 | B6: iPad Air | C6: Tablet | D6: Apple | E6: 599 | F6: Global Electronics
A7: P106 | B7: Galaxy Tab | C7: Tablet | D7: Samsung | E7: 499 | F7: Smart Supply
A8: P107 | B8: AirPods | C8: Audio | D8: Apple | E8: 179 | F8: Global Electronics
A9: P108 | B9: Buds Pro | C9: Audio | D9: Samsung | E9: 129 | F9: Global Electronics
A10: P109 | B10: Monitor 24 | C10: Monitor | D10: Dell | E10: 229 | F10: Global Electronics
A11: P110 | B11: Keyboard | C11: Accessory | D11: Logitech | E11: 59 | F11: DigitalHub
A12: P111 | B12: Mouse | C12: Accessory | D12: Logitech | E12: 39 | F12: TechWorld
A13: P112 | B13: PowerBank | C13: Accessory | D13: Anker | E13: 49 | F13: Global Electronics

Sheet Employee_Master
A1: EmployeeID | B1: EmployeeName | C1: Region | D1: HireDate | E1: Department | F1: BaseSalary
A2: E001 | B2: Amit Shah | C2: North | D2: 45307 | E2: Operations | F2: 58000
A3: E002 | B3: Priya Patel | C3: West | D3: 43212 | E3: Sales | F3: 50000
A4: E003 | B4: Rahul Mehta | C4: East | D4: 44384 | E4: Support | F4: 35000
A5: E004 | B5: Neha Joshi | C5: West | D5: 43488 | E5: Sales | F5: 50000
A6: E005 | B6: John Smith | C6: North | D6: 45016 | E6: Operations | F6: 50000
A7: E006 | B7: Sara Khan | C7: North | D7: 44506 | E7: Sales | F7: 35000

Sheet Monthly_Targets
A1: Month | B1: Region | C1: Target
A2: 45658 | B2: East | C2: 34786
A3: 45658 | B3: West | C3: 20721
A4: 45658 | B4: North | C4: 34391
A5: 45658 | B5: South | C5: 19952
A6: 45689 | B6: East | C6: 29635
A7: 45689 | B7: West | C7: 27116
A8: 45689 | B8: North | C8: 20747
A9: 45689 | B9: South | C9: 23560
A10: 45717 | B10: East | C10: 22739
A11: 45717 | B11: West | C11: 30889
A12: 45717 | B12: North | C12: 20924
A13: 45717 | B13: South | C13: 32281
... A49: 45992 | B49: South | C49: 24463

Sheet Cleaning_Practice
A1: RawName | B1: RawPhone | C1: RawAddress | D1: RawCategory | E1: RawEmail | F1: RawCode
A2: rAhUl shaH | B2: 98765-43210 | C2: 12, MG ROAD, AHMEDABAD | D2: mobile | E2: RAHUL@EXAMPLE.COM | F2: TX-2345
A3: PRIYA patel | B3: 9876543210 | C3: 12 MG ROAD AHMEDABAD | D3: MOBILE | E3: priya@example.com | F3: CA-8877
A4: Neha Joshi | B4: 98765 43210 | C4: 45, Ring Road, Surat | D4: laptop | E4: NEHA @ EXAMPLE.COM | F4: IN-1122
A5: john smith | B5: +91 9876543210 | C5: 78 MAIN STREET, BARODA | D5: LAPTOP | E5: john@example.com | F5: US-5566
A6: sARA khan | B6: 98765-00000 | C6: 9 lake view, ahmedabad | D6: audio | E6: sara@example.com | F6: TX-9999

Sheet Practice_Questions
A1: Topic | B1: Task | C1: Hint
A2: Level 1 - Navigation & References | B2: Convert Sales_Raw range to an Excel Table. Freeze the header row. Practice A1 and R1C1 reference styles. | C2: Use View > Freeze Panes and Ctrl+T.
A3: References | B3: In a new column calculate Gross Sales = Units*UnitPrice. Then calculate Net Sales using Discount. Use relative references correctly. | C3: Gross = Units*UnitPrice; Net = Gross*(1-Discount).
A4: Absolute / Mixed | B4: Put tax rate 18% in B1 and calculate tax for every order. Use an absolute reference for the tax rate. | C4: Reference B1 as $B$1.
A5: Named Ranges | B5: Create named ranges for Product_Master ProductID and UnitPrice. Use the names in a lookup formula. | C5: Formulas > Name Manager.
A6: Data Validation | B6: Create a dropdown for Region containing East, West, North, South. Create number validation for Rating 1-5. | C6: Data > Data Validation.
A7: Sorting | B7: Sort by Region, then Category, then Sales descending. | C7: Use multi-level Sort.
A8: Filtering | B8: Filter Sales > 5000 AND Region = East. Then filter Category = Mobile OR Laptop. | C8: Use AutoFilter; OR can be handled with multiple criteria/Advanced Filter.
A9: Advanced Filter | B9: Create a criteria range for Region=West AND Sales>5000 and copy results to another location. | C9: Use Data > Advanced.
A10: Text | B10: Extract first 3 characters of ProductID; last 2 characters of State Code like TX-2345; extract product category from ProductName if applicable. | C10: Use LEFT, RIGHT, MID, LEN.
A11: Text Cleaning | B11: Clean CustomerName by removing extra spaces and standardizing case. | C11: =PROPER(TRIM(F2))
A12: Cleaning | B12: Remove non-printing characters and replace double spaces/selected characters where needed. | C12: Use CLEAN, SUBSTITUTE.
A13: Dates | B13: Create Order Month, Order Year, Delivery Days, and Working Days from OrderDate to DeliveryDate. | C13: DAY, MONTH, YEAR, NETWORKDAYS.
A14: Date calculations | B14: Calculate employee tenure from HireDate to TODAY(), and month-end date for each order month. | C14: DATEDIF and EOMONTH.
A15: Logical | B15: Create Performance: Above Target / Below Target based on Sales vs Target. | C15: =IF(Sales>Target,"Above Target","Below Target")
A16: Logical | B16: Create a 5-grade rating based on Rating: 5=A, 4=B, 3=C, 2=D, 1=E. Use nested IF and/or IFS if available. | C16: Nested IF.
A17: AND/OR/XOR | B17: Flag orders that are (Sales>5000 AND Discount<=10%) OR Category=Mobile. Create a separate XOR example for two boolean conditions. | C17: Use AND, OR, XOR.
A18: IFERROR | B18: Create a safe lookup that returns "Not Found" instead of an error. | C18: Wrap lookup in IFERROR.
A19: VLOOKUP exact | B19: Using Product_Master, return ProductName and UnitPrice from ProductID. | C19: =VLOOKUP(H2,Product_Master!$A$2:$F$13,2,FALSE)
A20: VLOOKUP approximate | B20: Create a small commission-rate table by sales amount and use approximate VLOOKUP to assign a rate. | C20: Sort thresholds ascending; use TRUE.
A21: HLOOKUP | B21: Make a horizontal lookup table of Region targets and retrieve the target for a selected Region. | C21: Use HLOOKUP exact match.
A22: XLOOKUP | B22: Return ProductName, Brand, and Supplier from ProductID. Test a missing ProductID with a custom not-found message. | C22: =XLOOKUP(H2,Product_Master!A:A,Product_Master!B:B,"Not Found")
A23: Reverse XLOOKUP | B23: For a selected CustomerName, return the last matching OrderID. Use search mode -1. | C23: XLOOKUP(...,,-1)
A24: INDEX MATCH | B24: Return UnitPrice for a selected ProductID using INDEX + MATCH. | C24: =INDEX(Product_Master!E:E,MATCH(A2,Product_Master!A:A,0))
A25: Two-way INDEX MATCH | B25: Build a small Region x Month sales summary and return the intersection for West + March. | C25: INDEX with two MATCH functions.
A26: Conditional Formatting | B26: Highlight duplicate OrderIDs, Sales above Target, top 10 Sales, and low Ratings <=2. | C26: Use Duplicate Values, formula rules, Top/Bottom Rules, icon sets.
A27: Pivot Basics | B27: Create PivotTables: Sales by Region; Sales by Category; Average Sales by Salesperson; Count of Orders by PaymentMethod. | C27: Rows/Columns/Values.
A28: Pivot Advanced | B28: Group OrderDate by Month and Quarter. Add slicers for Region and Category. Drill into a high-sales value. | C28: PivotTable Analyze > Group/Slicer.
A29: Pivot Calculated Field | B29: Create a calculated field for gross margin proxy = Sales - Units*Cost. Add a Cost column from a suitable assumption or Product_Master extension. | C29: Use Calculated Field or helper column.
A30: PivotCharts | B30: Create Bar, Line, Area, and Pie charts from PivotTables. Add slicers and test interactions. | C30: PivotChart + slicers.
A31: Data Cleaning | B31: Use Remove Duplicates, Text to Columns, Flash Fill, Find/Replace wildcards, and error checking on Cleaning_Practice. | C31: Work on a copy so raw data stays intact.
A32: Power Query | B32: Import Sales_Raw into Power Query. Change data types, trim/clean names, remove blank rows, and load the cleaned table. | C32: Data > From Table/Range.
A33: Power Query Merge | B33: Merge Sales_Raw with Product_Master using ProductID. Expand Brand, Supplier, and UnitPrice. | C33: Merge Queries; Left Outer.
A34: Power Query Append | B34: Create two small monthly sales tables and append them into one table. Resolve mismatched columns and nulls. | C34: Append Queries.
A35: Dashboard KPIs | B35: Build KPI cards for Total Sales, Average Order Value, Max Order, Min Order, Order Count, and % Above Target. | C35: Use formulas or Pivot measures.
A36: Dashboard | B36: Create an executive dashboard with KPI cards, monthly sales trend, region sales, category sales, slicers for Region/Category, and a date timeline. | C36: Use PivotTables + PivotCharts + Slicers + Timeline.
A37: Final Case Study | B37: Start from Sales_Raw. Clean it, enrich it with Product_Master, create calculated columns, summary tables, PivotTables, PivotCharts, and a one-page dashboard. Write 5 factual insights from your results. | C37: Do not change the raw data; keep a Cleaned_Data sheet.

Sheet Answer_Key
A1: Task | B1: Example Answer / Formula
A2: Gross Sales | B2: =J2*K2
A3: Net Sales | B3: =J2*K2*(1-L2)
A4: Tax with absolute reference | B4: =M2*$B$1
A5: Clean Name | B5: =PROPER(TRIM(F2))
A6: ProductID prefix | B6: =LEFT(H2,4)
A7: Code suffix | B7: =RIGHT(U2,4) if U2 contains a code like TX-2345
A8: Safe lookup | B8: =IFERROR(XLOOKUP(H2,Product_Master!A:A,Product_Master!B:B),"Not Found")
A9: Delivery Days | B9: =P2-O2
A10: Working Days | B10: =NETWORKDAYS(O2,P2)
A11: Order Year | B11: =YEAR(B2)
A12: Order Month | B12: =MONTH(B2)
A13: Month End | B13: =EOMONTH(B2,0)
A14: Performance | B14: =IF(M2>N2,"Above Target","Below Target")
A15: AND condition | B15: =AND(M2>5000,L2<=10%)
A16: OR condition | B16: =OR(M2>5000,C2="East")
A17: XOR condition | B17: =XOR(C2="East",G2="Mobile")
A18: VLOOKUP Product | B18: =VLOOKUP(H2,Product_Master!$A$2:$F$13,2,FALSE)
A19: VLOOKUP Price | B19: =VLOOKUP(H2,Product_Master!$A$2:$F$13,5,FALSE)
A20: XLOOKUP Price | B20: =XLOOKUP(H2,Product_Master!A:A,Product_Master!E:E,"Not Found")
A21: INDEX MATCH Price | B21: =INDEX(Product_Master!E:E,MATCH(H2,Product_Master!A:A,0))
A22: Pivot Sales by Region | B22: Rows=Region; Values=Sales (Sum)
A23: Pivot Average Salesperson | B23: Rows=Salesperson; Values=Sales (Average)
A24: Conditional Formatting | B24: Use formula =$M2>$N2 to highlight Sales above Target across the row.
